Workbook
Name ASOFDATE: #REF!
Name Period: [1]Data!$K$2:$K$5
Name TICKER: #REF!

Sheet 3 Statement Model
A1: Fairwood (0052.HK) Financial Statements
A2: Income Statement (in $ millions) | B2: 2021 | C2: 2022 | D2: 2023 | E2: 2024 | F2: 2025 | G2: 2026 | I2: Balance Sheet (in $ millions) | J2: 2021 | K2: 2022 | L2: 2023 | M2: 2024 | N2: 2025 | O2: 2026 | Q2: Statement of Cash Flows (in $ millions) | R2: 2021 | S2: 2022 | T2: 2023 | U2: 2024 | V2: 2025 | W2: 2026
A3: Revenue | B3: 3030.198 | C3: 2646.469 | D3: 2881.942 | E3: 3024.152 | F3: 3136.947 | G3: 3100.07 | I3: Non-current assets | Q3: Operating activities
A4: Cost of sales | B4: 2752.83 | C4: 2318.873 | D4: 2659.381 | E4: 2767.394 | F4: 2866.353 | G4: 2862.864 | I4: Investment properties | J4: 29.83 | K4: 28.1 | L4: 23.26 | M4: 22.24 | N4: 21.09 | O4: 21.904 | Q4: Profit before taxation | R4: 138.399 | S4: 47.804 | T4: 51.664 | U4: 65.125 | V4: 38.649 | W4: 51.622
A5: Gross profit | B5: 277.368 | C5: 327.596 | D5: 222.561 | E5: 256.758 | F5: 270.594 | G5: 237.206 | I5: Other property, plant and equipment | J5: 424.866 | K5: 385.197 | L5: 379.399 | M5: 396.593 | N5: 433.077 | O5: 466.65 | Q5: Non-cash adjustments | R5: 656.853 | S5: 550.503 | T5: 522.475 | U5: 533.767 | V5: 543.845 | W5: 549.544
A6: Other revenue | B6: 23.095 | C6: 99.921 | D6: 76.263 | E6: 41.514 | F6: 42.405 | G6: 58.2 | I6: Right-of-use assets | J6: 1110.609 | K6: 1078.744 | L6: 1033.885 | M6: 970.574 | N6: 881.001 | O6: 890.711 | Q6: Finance costs | R6: 36.824 | S6: 32.404 | T6: 31.698 | U6: 33.366 | V6: 33.677 | W6: 32.638
B7: 300.463 | C7: 427.517 | D7: 298.824 | E7: 298.272 | F7: 312.999 | G7: 295.406 | I7: Other non-current assets | J7: 79.44 | K7: 74.742 | L7: 72.553 | M7: 61.005 | N7: 65.979 | O7: 59.67 | Q7: Interest income | R7: -4.437 | S7: -3.295 | T7: -14.757 | U7: -28.113 | V7: -24.257 | W7: -16.347
A8: Selling expenses | B8: 32.722 | C8: 34.511 | D8: 37.165 | E8: 37.379 | F8: 35.53 | G8: 43.68 | I8: Goodwill | J8: 1.001 | K8: 1.001 | L8: 1.001 | M8: 1.001 | N8: 1.001 | O8: 1.001 | Q8: Changes in working capital | R8: -46.413 | S8: -69.535 | T8: 102.21 | U8: 23.164 | V8: -15.877 | W8: 38.277
A9: Administrative expenses | B9: 126.078 | C9: 115.526 | D9: 130.449 | E9: 132.058 | F9: 145.324 | G9: 141.868 | I9: Total non-current assets | J9: 1645.746 | K9: 1567.784 | L9: 1510.098 | M9: 1451.413 | N9: 1402.148 | O9: 1439.936 | Q9: Interest received | R9: 4.701 | S9: 3.542 | T9: 11.858 | U9: 28.058 | V9: 23.395 | W9: 17.545
A10: Impairment losses on non-current assets | B10: 31.588 | C10: 102.257 | D10: 51.002 | E10: 45.473 | F10: 33.654 | G10: 37.532 | I10: Current assets | Q10: Net Profits Tax (paid)/refund | R10: -5.126 | S10: -0.06 | T10: 4.245 | U10: -5.259 | V10: -12.98 | W10: -4.448
A11: EBIT | B11: 110.075 | C11: 175.223 | D11: 80.208 | E11: 83.362 | F11: 98.491 | G11: 72.326 | I11: Inventories | J11: 46.008 | K11: 57.278 | L11: 55.624 | M11: 52.651 | N11: 54.282 | O11: 56.945 | Q11: Net cash generated from operating activities | R11: 780.789 | S11: 561.363 | T11: 709.393 | U11: 650.108 | V11: 586.452 | W11: 668.831
A12: Finance costs | B12: 37.995 | C12: 36.824 | D12: 32.404 | E12: 31.698 | F12: 33.366 | G12: 33.677 | I12: Other current assets | J12: 34.378 | K12: 10.44 | L12: 0.032 | M12: 0.039 | N12: 0.052 | O12: 0.914 | Q12: Investing activities
A13: EBT | B13: 72.08 | C13: 138.399 | D13: 47.804 | E13: 51.664 | F13: 65.125 | G13: 38.649 | I13: Trade and other receivables | J13: 99.764 | K13: 144.664 | L13: 90.033 | M13: 102.725 | N13: 103.194 | O13: 98.533 | Q13: Payment for purchase of other PPE | R13: -109.878 | S13: -76.483 | T13: -99.03 | U13: -119.567 | V13: -163.015 | W13: -137.283
A14: Income Tax Expense/(Benefit) | B14: 11.213 | C14: -15.218 | D14: 5.164 | E14: 6.784 | F14: 14.468 | G14: 3.109 | I14: Bank deposits and cash and cash equivalents | J14: 622.143 | K14: 557.102 | L14: 646.758 | M14: 640.983 | N14: 545.653 | O14: 575.259 | Q14: Deposits paid for purchase of other PPE | R14: 0 | S14: 0 | T14: 0 | U14: 0 | V14: -8.168 | W14: -16.618
A15: Net Income | B15: 60.867 | C15: 153.617 | D15: 42.64 | E15: 44.88 | F15: 50.657 | G15: 35.54 | I15: Total current assets | J15: 802.293 | K15: 769.484 | L15: 792.447 | M15: 796.398 | N15: 703.181 | O15: 731.651 | Q15: Net proceeds from disposal of other PPE | R15: 0.299 | S15: 0.142 | T15: 0.031 | U15: 0.762 | V15: 0.093 | W15: 0.086
I16: Total Assets | J16: =J9+J15 -> 2448.039 | K16: =K9+K15 -> 2337.268 | L16: =L9+L15 -> 2302.545 | M16: =M9+M15 -> 2247.811 | N16: =N9+N15 -> 2105.329 | O16: =O9+O15 -> 2171.587 | Q16: Placement of bank deposits with more than three months to maturity | R16: -6.511 | S16: 6.511 | T16: -60 | U16: -102.661 | V16: -207.475 | W16: -266.048
I17: Current liabilities | Q17: Withdrawal of bank deposits with more than three months to maturity | R17: 0 | S17: 0 | T17: 0 | U17: 60 | V17: 102.661 | W17: 207.475
I18: Trade and other payables | J18: 359.778 | K18: 344.428 | L18: 400.536 | M18: 435.009 | N18: 402.51 | O18: 425.469 | Q18: Other cash flow transactions related to Investing activities | R18: 4.74 | S18: 19.047 | T18: 2.268 | U18: 0.628 | V18: 0 | W18: 0
I19: Lease liabilities (current) | J19: 433.32 | K19: 410.072 | L19: 393.575 | M19: 389.911 | N19: 372.43 | O19: 365.226 | Q19: Net cash used in investing activities | R19: -111.35 | S19: -50.783 | T19: -156.731 | U19: -160.838 | V19: -275.904 | W19: -212.388
I20: Bank borrowings (non-current) | J20: 0 | K20: 0 | L20: 0 | M20: 0 | N20: 5.419 | O20: 0.227 | Q20: Financing activities
I21: Other current liabilities | J21: 79.44 | K21: 74.742 | L21: 72.553 | M21: 61.005 | N21: 65.979 | O21: 59.67 | Q21: Capital element of lease rentals paid | R21: -424.974 | S21: -427.548 | T21: -413.868 | U21: -431.355 | V21: -436.633 | W21: -425.096
I22: Total current liabilities | J22: 811.902 | K22: 782.322 | L22: 817.224 | M22: 858.343 | N22: 812.659 | O22: 819.573 | Q22: Finance costs paid | R22: -36.824 | S22: -32.404 | T22: -31.698 | U22: -33.366 | V22: -33.677 | W22: -32.638
I23: Non-current liabilities | Q23: Dividends paid | R23: -103.627 | S23: -110.119 | T23: -75.141 | U23: -72.549 | V23: -45.344 | W23: -28.502
I24: Lease liabilities (non-current) | J24: 785.222 | K24: 776.158 | L24: 732.878 | M24: 652.27 | N24: 565.7 | O24: 580.188 | Q24: New bank borrowings raised | R24: 0 | S24: 0 | T24: 0 | U24: 4.965 | V24: 23.954 | W24: 31.793
I25: Other non-current liabilities | J25: 73.079 | K25: 64.552 | L25: 71.814 | M25: 76.793 | N25: 74.935 | O25: 97.764 | Q25: Repayment of bank borrowings | R25: 0 | S25: 0 | T25: 0 | U25: -4.965 | V25: -18.535 | W25: -31.906
I26: bank borrowings (current) | J26: 0 | K26: 0 | L26: 0 | M26: 0 | N26: 0 | O26: 5.337 | Q26: Net cash used in financing activities | R26: -565.425 | S26: -569.734 | T26: -520.707 | U26: -537.27 | V26: -510.235 | W26: -486.349
I27: Total non-current liabilities | J27: 858.301 | K27: 840.71 | L27: 804.692 | M27: 729.063 | N27: 640.635 | O27: 683.289
I28: Capital and reserves
I29: Share capital | J29: 129.533 | K29: 129.553 | L29: 129.553 | M29: 129.553 | N29: 129.553 | O29: 129.553
I30: Reserves | J30: 648.303 | K30: 584.683 | L30: 551.076 | M30: 530.852 | N30: 522.482 | O30: 539.172
I31: Total equity | J31: 777.836 | K31: 714.236 | L31: 680.629 | M31: 660.405 | N31: 652.035 | O31: 668.725
I32: Total Equity and Liabilities | J32: =J22+J27+J31 -> 2448.039 | K32: =K22+K27+K31 -> 2337.268 | L32: =L22+L27+L31 -> 2302.545 | M32: =M22+M27+M31 -> 2247.811 | N32: =N22+N27+N31 -> 2105.329 | O32: =O22+O27+O31 -> 2171.587
A33: Source: Bloomberg Terminal

Sheet Comparable Company Analysis
A1: Financial Ratio Analysis
A2: Dupont Analysis | C2: Net Income Margin | H2: Asset Turnover | M2: Equity Multiplier
B3: Stock | C3: 2022 | D3: 2023 | E3: 2024 | F3: 2025 | G3: 2026 | H3: 2022 | I3: 2023 | J3: 2024 | K3: 2025 | L3: 2026 | M3: 2022 | N3: 2023 | O3: 2024 | P3: 2025 | Q3: 2026
B4: 0052.HK | C4: =D53/D46 -> 0.014795579 | D4: =E53/E46 -> 0.014840524 | E4: =F53/F46 -> 0.016148504 | F4: =G53/G46 -> 0.011464257 | G4: =H53/H46 -> 0.013411509 | H4: =D46/((D56+D60+C56+C60)/2) -> 1.2044962 | I4: =E46/((E56+E60+D56+D60)/2) -> 1.3035663 | J4: =F46/((F56+F60+E56+E60)/2) -> 1.3787699 | K4: =G46/((G56+G60+F56+F60)/2) -> 1.4242914 | L4: =H46/((H56+H60+G56+G60)/2) -> 1.449096 | M4: =(((D56+D60+C56+C60)/2))/((D66+C66)/2) -> 3.2071556 | N4: =(((E56+E60+D56+D60)/2))/((E66+D66)/2) -> 3.3263527 | O4: =(((F56+F60+E56+E60)/2))/((F66+E66)/2) -> 3.3931697 | P4: =(((G56+G60+F56+F60)/2))/((G66+F66)/2) -> 3.3168297 | Q4: =(((H56+H60+G56+G60)/2))/((H66+G66)/2) -> 3.2382234
B5: 0341.HK | C5: =D84/D76 -> 0.0030431151 | D5: =E84/E76 -> 0.013856729 | E5: =F84/F76 -> 0.038338256 | F5: =G84/G76 -> 0.027439578 | G5: =H84/H76 -> 0.020322021 | H5: =D76/((D88+D93+C88+C93)/2) -> 1.070651 | I5: =E76/((E88+E93+D88+D93)/2) -> 1.1424415 | J5: =F76/((F88+F93+E88+E93)/2) -> 1.2698198 | K5: =G76/((G88+G93+F88+F93)/2) -> 1.3715722 | L5: =H76/((H88+H93+G88+G93)/2) -> 1.3927829 | M5: =(((D88+D93+C88+C93)/2))/((D95+C95)/2) -> 2.393109 | N5: =(((E88+E93+D88+D93)/2))/((E95+D95)/2) -> 2.5001937 | O5: =(((F88+F93+E88+E93)/2))/((F95+E95)/2) -> 2.4005404 | P5: =(((G88+G93+F88+F93)/2))/((G95+F95)/2) -> 2.2093022 | Q5: =(((H88+H93+G88+G93)/2))/((H95+G95)/2) -> 2.1469717
B6: 1314.HK | C6: =D115/D108 -> 0.12488272 | D6: =E115/E108 -> 0.066067863 | E6: =F115/F108 -> 0.034555112 | F6: =G115/G108 -> 0.012559048 | G6: =H115/H108 -> 0.0084738371 | H6: =D108/((D119+D124+C119+C124)/2) -> 0.70444614 | I6: =E108/((E119+E124+D119+D124)/2) -> 0.7330734 | J6: =F108/((F119+F124+E119+E124)/2) -> 0.98876288 | K6: =G108/((G119+G124+F119+F124)/2) -> 1.0546159 | L6: =H108/((H119+H124+G119+G124)/2) -> 1.0405777 | M6: =(((D119+D124+C119+C124)/2))/((D131+C131)/2) -> 2.5096407 | N6: =(((E119+E124+D119+D124)/2))/((E131+D131)/2) -> 2.216056 | O6: =(((F119+F124+E119+E124)/2))/((F131+E131)/2) -> 1.8930772 | P6: =(((G119+G124+F119+F124)/2))/((G131+F131)/2) -> 1.8554894 | Q6: =(((H119+H124+G119+G124)/2))/((H131+G131)/2) -> 1.8876195
B7: 1978.HK | C7: =D147/D140 -> 0.090263839 | D7: =E147/E140 -> 0.073088785 | E7: =F147/F140 -> 0.068974781 | F7: =G147/G140 -> 0.030361972 | G7: =H147/H140 -> 0.0015276804 | H7: =D140/((D150+D155+C150+C155)/2) -> 1.3033142 | I7: =E140/((E150+E155+D150+D155)/2) -> 1.3041287 | J7: =F140/((F150+F155+E150+E155)/2) -> 1.5897607 | K7: =G140/((G150+G155+F150+F155)/2) -> 1.3663989 | L7: =H140/((H150+H155+G150+G155)/2) -> 1.4587117 | M7: =(((D150+D155+C150+C155)/2))/((D162+C162)/2) -> 1.9267235 | N7: =(((E150+E155+D150+D155)/2))/((E162+D162)/2) -> 2.0646487 | O7: =(((F150+F155+E150+E155)/2))/((F162+E162)/2) -> 2.2722062 | P7: =(((G150+G155+F150+F155)/2))/((G162+F162)/2) -> 2.914838 | Q7: =(((H150+H155+G150+G155)/2))/((H162+G162)/2) -> 3.1719688
B8: 6811.HK | C8: =D181/D173 -> 0.030051746 | D8: =E181/E173 -> 0.016101431 | E8: =F181/F173 -> 0.029218619 | F8: =G181/G173 -> 0.019043705 | G8: =H181/H173 -> 0.030549994 | H8: =D173/((D185+D189+C185+C189)/2) -> 1.0659521 | I8: =E173/((E185+E189+D185+D189)/2) -> 1.0188306 | J8: =F173/((F185+F189+E185+E189)/2) -> 1.2610192 | K8: =G173/((G185+G189+F185+F189)/2) -> 1.3030297 | L8: =H173/((H185+H189+G185+G189)/2) -> 1.4431439 | M8: =(((D185+D189+C185+C189)/2))/((D197+C197)/2) -> 2.7331932 | N8: =(((E185+E189+D185+D189)/2))/((E197+D197)/2) -> 2.5612502 | O8: =(((F185+F189+E185+E189)/2))/((F197+E197)/2) -> 2.6262998 | P8: =(((G185+G189+F185+F189)/2))/((G197+F197)/2) -> 2.6314162 | Q8: =(((H185+H189+G185+G189)/2))/((H197+G197)/2) -> 2.6748518
A10: Profitability Analysis | C10: Return on Equity | H10: Return on Assets | M10: EBITDA Margin
B11: Stock | C11: 2022 | D11: 2023 | E11: 2024 | F11: 2025 | G11: 2026 | H11: 2022 | I11: 2023 | J11: 2024 | K11: 2025 | L11: 2026 | M11: 2022 | N11: 2023 | O11: 2024 | P11: 2025 | Q11: 2026
B12: 0052.HK | C12: =D53/((D66+C66)/2) -> 0.057155419 | D12: =E53/((E66+D66)/2) -> 0.064350313 | E12: =F53/((F66+E66)/2) -> 0.075549166 | F12: =G53/((G66+F66)/2) -> 0.054158666 | G12: =H53/((H66+G66)/2) -> 0.062933463 | H12: =D53/((D56+D60+C56+C60)/2) -> 0.017821218 | I12: =E53/((E56+E60+D56+D60)/2) -> 0.019345607 | J12: =F53/((F56+F60+E56+E60)/2) -> 0.022265071 | K12: =G53/((G56+G60+F56+F60)/2) -> 0.016328443 | L12: =H53/((H56+H60+G56+G60)/2) -> 0.019434565 | M12: =(D49+D68)/D46 -> 0.20110953 | N12: =(E49+E68)/E46 -> 0.18584483 | O12: =(F49+F68)/F46 -> 0.19093214 | P12: =(G49+G68)/G46 -> 0.19202534 | Q12: =(H49+H68)/H46 -> 0.19422066
B13: 0341.HK | C13: =D84/((D95+C95)/2) -> 0.0077970222 | D13: =E84/((E95+D95)/2) -> 0.039579321 | E13: =F84/((F95+E95)/2) -> 0.11686473 | F13: =G84/((G95+F95)/2) -> 0.083147886 | G13: =H84/((H95+G95)/2) -> 0.06076824 | H13: =D84/((D88+D93+C88+C93)/2) -> 0.0032581141 | I13: =E84/((E88+E93+D88+D93)/2) -> 0.015830502 | J13: =F84/((F88+F93+E88+E93)/2) -> 0.048682676 | K13: =G84/((G88+G93+F88+F93)/2) -> 0.037635361 | L13: =H84/((H88+H93+G88+G93)/2) -> 0.028304164 | M13: =(D79+D105)/D76 -> 0.16530761 | N13: =(E79+E105)/E76 -> 0.1721111 | O13: =(F79+F105)/F76 -> 0.19013458 | P13: =(G79+G105)/G76 -> 0.17676855 | Q13: =(H79+H105)/H76 -> 0.16947742
B14: 1314.HK | C14: =D115/((D131+C131)/2) -> 0.22078099 | D14: =E115/((E131+D131)/2) -> 0.10732934 | E14: =F115/((F131+E131)/2) -> 0.064680414 | F14: =G115/((G131+F131)/2) -> 0.024575904 | G14: =H115/((H131+G131)/2) -> 0.016644436 | H14: =D115/((D119+D124+C119+C124)/2) -> 0.087973148 | I14: =E115/((E119+E124+D119+D124)/2) -> 0.048432593 | J14: =F115/((F119+F124+E119+E124)/2) -> 0.034166812 | K14: =G115/((G119+G124+F119+F124)/2) -> 0.013244971 | L14: =H115/((H119+H124+G119+G124)/2) -> 0.0088176863 | M14: =(D138+D110)/D108 -> 0.38645799 | N14: =(E138+E110)/E108 -> 0.29712567 | O14: =(F138+F110)/F108 -> 0.18863507 | P14: =(G138+G110)/G108 -> 0.15963865 | Q14: =(H138+H110)/H108 -> 0.16470235
B15: 1978.HK | C15: =D147/((D162+C162)/2) -> 0.22666388 | D15: =E147/((E162+D162)/2) -> 0.1967965 | E15: =F147/((F162+E162)/2) -> 0.24915512 | F15: =G147/((G162+F162)/2) -> 0.12092662 | G15: =H147/((H162+G162)/2) -> 0.007068559 | H15: =D147/((D150+D155+C150+C155)/2) -> 0.11764214 | I15: =E147/((E150+E155+D150+D155)/2) -> 0.095317185 | J15: =F147/((F150+F155+E150+E155)/2) -> 0.1096534 | K15: =G147/((G150+G155+F150+F155)/2) -> 0.041486565 | L15: =H147/((H150+H155+G150+G155)/2) -> 0.0022284453 | M15: =(D169+D141)/D140 -> 0.4210973 | N15: =(E169+E141)/E140 -> 0.42460253 | O15: =(F169+F141)/F140 -> 0.39181106 | P15: =(G169+G141)/G140 -> 0.38754271 | Q15: =(H169+H141)/H140 -> 0.36276584
B16: 6811.HK | C16: =D181/((D197+C197)/2) -> 0.087554346 | D16: =E181/((E197+D197)/2) -> 0.042016364 | E16: =F181/((F197+E197)/2) -> 0.096766643 | F16: =G181/((G197+F197)/2) -> 0.065297309 | G16: =H181/((H197+G197)/2) -> 0.11792896 | H16: =D181/((D185+D189+C185+C189)/2) -> 0.03203372 | I16: =E181/((E185+E189+D185+D189)/2) -> 0.016404631 | J16: =F181/((F185+F189+E185+E189)/2) -> 0.036845239 | K16: =G181/((G185+G189+F185+F189)/2) -> 0.024814513 | L16: =H181/((H185+H189+G185+G189)/2) -> 0.044088037 | M16: =(D202+D176)/D173 -> 0.23250259 | N16: =(E202+E176)/E173 -> 0.22571459 | O16: =(F202+F176)/F173 -> 0.21146746 | P16: =(G202+G176)/G173 -> 0.20303838 | Q16: =(H202+H176)/H173 -> 0.19942829
A18: Working Capital Analysis | C18: AR Turnover | H18: Days' AR | M18: Inventory Turnover | R18: Days' Inventory | W18: AP Turnover | AB18: Days' AP | AG18: Cash Conversion Cycle
B19: Stock | C19: 2022 | D19: 2023 | E19: 2024 | F19: 2025 | G19: 2026 | H19: 2022 | I19: 2023 | J19: 2024 | K19: 2025 | L19: 2026 | M19: 2022 | N19: 2023 | O19: 2024 | P19: 2025 | Q19: 2026 | R19: 2022 | S19: 2023 | T19: 2024 | U19: 2025 | V19: 2026 | W19: 2022 | X19: 2023 | Y19: 2024 | Z19: 2025 | AA19: 2026 | AB19: 2022 | AC19: 2023 | AD19: 2024 | AE19: 2025 | AF19: 2026 | AG19: 2022 | AH19: 2023 | AI19: 2024 | AJ19: 2025 | AK19: 2026
B20: 0052.HK | C20: =D46/(((D70+D71)+(C70+C71))/2) -> 59.566409 | D20: =E46/(((E70+E71)+(D70+D71))/2) -> 62.899644 | E20: =F46/(((F70+F71)+(E70+E71))/2) -> 99.910725 | F20: =G46/(((G70+G71)+(F70+F71))/2) -> 102.69723 | G20: =H46/(((H70+H71)+(G70+G71))/2) -> 121.98921 | H20: =360/C20 -> 6.0436747 | I20: =360/D20 -> 5.7234028 | J20: =360/E20 -> 3.6032168 | K20: =360/F20 -> 3.5054499 | L20: =360/G20 -> 2.9510806 | M20: =D47/((D57+C57)/2) -> 51.495479 | N20: =E47/((E57+D57)/2) -> 49.02294 | O20: =F47/((F57+E57)/2) -> 52.945795 | P20: =G47/((G57+F57)/2) -> 53.545005 | Q20: =H47/((H57+G57)/2) -> 50.893938 | R20: =360/M20 -> 6.990905 | S20: =360/N20 -> 7.3435008 | T20: =360/O20 -> 6.7994068 | U20: =360/P20 -> 6.7233162 | V20: =360/Q20 -> 7.073534 | W20: =D47/(((D74+D75)+(C74+C75))/2) -> 7.7454954 | X20: =E47/(((E74+E75)+(D74+D75))/2) -> 7.5756022 | Y20: =F47/(((F74+F75)+(E74+E75))/2) -> 6.9724324 | Z20: =G47/(((G74+G75)+(F74+F75))/2) -> 6.9435925 | AA20: =H47/(((H74+H75)+(G74+G75))/2) -> 6.8798477 | AB20: =360/W20 -> 46.478628 | AC20: =360/X20 -> 47.520975 | AD20: =360/Y20 -> 51.63191 | AE20: =360/Z20 -> 51.846361 | AF20: =360/AA20 -> 52.326739 | AG20: =H20+R20-AB20 -> -33.444048 | AH20: =I20+S20-AC20 -> -34.454071 | AI20: =J20+T20-AD20 -> -41.229286 | AJ20: =K20+U20-AE20 -> -41.617595 | AK20: =L20+V20-AF20 -> -42.302125
B21: 0341.HK | C21: =D76/(((D102+D103)+(C102+C103))/2) -> 49.712191 | D21: =E76/(((E102+E103)+(D102+D103))/2) -> 47.537777 | E21: =F76/(((F102+F103)+(E102+E103))/2) -> 59.828385 | F21: =G76/(((G102+G103)+(F102+F103))/2) -> 61.859522 | G21: =H76/(((H102+H103)+(G102+G103))/2) -> 70.21204 | H21: =360/C21 -> 7.2416845 | I21: =360/D21 -> 7.5729246 | J21: =360/E21 -> 6.0172107 | K21: =360/F21 -> 5.8196376 | L21: =360/G21 -> 5.1273258 | M21: =D77/((D89+C89)/2) -> 25.855047 | N21: =E77/((E89+D89)/2) -> 25.608909 | O21: =F77/((F89+E89)/2) -> 30.899435 | P21: =G77/((G89+F89)/2) -> 34.044074 | Q21: =H77/((H89+G89)/2) -> 33.892489 | R21: =360/M21 -> 13.92378 | S21: =360/N21 -> 14.057608 | T21: =360/O21 -> 11.650699 | U21: =360/P21 -> 10.574528 | V21: =360/Q21 -> 10.621822 | W21: =D77/(((D99+D106)+(C99+C106))/2) -> 8.3425999 | X21: =E77/(((E99+E106)+(D99+D106))/2) -> 7.8094588 | Y21: =F77/(((F99+F106)+(E99+E106))/2) -> 7.5514622 | Z21: =G77/(((G99+G106)+(F99+F106))/2) -> 7.7351453 | AA21: =H77/(((H99+H106)+(G99+G106))/2) -> 7.5706326 | AB21: =360/W21 -> 43.152015 | AC21: =360/X21 -> 46.097944 | AD21: =360/Y21 -> 47.672886 | AE21: =360/Z21 -> 46.54082 | AF21: =360/AA21 -> 47.552169 | AG21: =H21+R21-AB21 -> -21.986551 | AH21: =I21+S21-AC21 -> -24.467412 | AI21: =J21+T21-AD21 -> -30.004977 | AJ21: =K21+U21-AE21 -> -30.146654 | AK21: =L21+V21-AF21 -> -31.80302
B22: 1314.HK | C22: =D108/(((D121+D134)+(C121+C134))/2) -> 18.26534 | D22: =E108/(((E121+E134)+(D121+D134))/2) -> 17.668992 | E22: =F108/(((F121+F134)+(E121+E134))/2) -> 26.156259 | F22: =G108/(((G121+G134)+(F121+F134))/2) -> 37.751667 | G22: =H108/(((H121+H134)+(G121+G134))/2) -> 46.973051 | H22: =360/C22 -> 19.70946 | I22: =360/D22 -> 20.374676 | J22: =360/E22 -> 13.763436 | K22: =360/F22 -> 9.5360028 | L22: =360/G22 -> 7.6639689 | M22: =D109/((D120+C120)/2) -> 17.597605 | N22: =E109/((E120+D120)/2) -> 20.332526 | O22: =F109/((F120+E120)/2) -> 27.486403 | P22: =G109/((G120+F120)/2) -> 24.685009 | Q22: =H109/((H120+G120)/2) -> 24.198818 | R22: =360/M22 -> 20.45733 | S22: =360/N22 -> 17.705621 | T22: =360/O22 -> 13.097385 | U22: =360/P22 -> 14.58375 | V22: =360/Q22 -> 14.876759 | W22: =D109/(((D125+D136)+(C125+C136))/2) -> 3.8312239 | X22: =E109/(((E125+E136)+(D125+D136))/2) -> 3.4863875 | Y22: =F109/(((F125+F136)+(E125+E136))/2) -> 3.3872863 | Z22: =G109/(((G125+G136)+(F125+F136))/2) -> 3.7516943 | AA22: =H109/(((H125+H136)+(G125+G136))/2) -> 4.1104371 | AB22: =360/W22 -> 93.964752 | AC22: =360/X22 -> 103.25875 | AD22: =360/Y22 -> 106.27977 | AE22: =360/Z22 -> 95.956645 | AF22: =360/AA22 -> 87.581927 | AG22: =H22+R22-AB22 -> -53.797962 | AH22: =I22+S22-AC22 -> -65.178448 | AI22: =J22+T22-AD22 -> -79.418945 | AJ22: =K22+U22-AE22 -> -71.836893 | AK22: =L22+V22-AF22 -> -65.041199
B23: 1978.HK | C23: =D140/(((D170+D164)+(C170+C164))/2) -> 393.1911 | D23: =E140/(((E170+E164)+(D170+D164))/2) -> 430.34163 | E23: =F140/(((F170+F164)+(E170+E164))/2) -> 432.21767 | F23: =G140/(((G170+G164)+(F170+F164))/2) -> 341.24802 | G23: =H140/(((H170+H164)+(G170+G164))/2) -> 338.40651 | H23: =360/C23 -> 0.91558533 | I23: =360/D23 -> 0.83654467 | J23: =360/E23 -> 0.83291365 | K23: =360/F23 -> 1.0549512 | L23: =360/G23 -> 1.0638093 | M23: =D167/((D153+C153)/2) -> 0 | N23: =E167/((E153+D153)/2) -> 0 | O23: =F167/((F153+E153)/2) -> 0 | P23: =G167/((G153+F153)/2) -> 0 | Q23: =H167/((H153+G153)/2) -> 0 | R23: 0 | S23: 0 | T23: 0 | U23: 0 | V23: 0 | W23: =D167/(((D156+D166)+(C156+C166))/2) -> 0 | X23: =E167/(((E156+E166)+(D156+D166))/2) -> 0 | Y23: =F167/(((F156+F166)+(E156+E166))/2) -> 0 | Z23: =G167/(((G156+G166)+(F156+F166))/2) -> 0 | AA23: =H167/(((H156+H166)+(G156+G166))/2) -> 0 | AB23: =(((D156+D166)+(C156+C166))/2)/(D140-D169)*360 -> 23.415706 | AC23: =(((E156+E166)+(D156+D166))/2)/(E140-E169)*360 -> 25.305907 | AD23: =(((F156+F166)+(E156+E166))/2)/(F140-F169)*360 -> 16.279112 | AE23: =(((G156+G166)+(F156+F166))/2)/(G140-G169)*360 -> 18.204088 | AF23: =(((H156+H166)+(G156+G166))/2)/(H140-H169)*360 -> 18.120483 | AG23: =H23+R23-AB23 -> -22.500121 | AH23: =I23+S23-AC23 -> -24.469362 | AI23: =J23+T23-AD23 -> -15.446199 | AJ23: =K23+U23-AE23 -> -17.149137 | AK23: =L23+V23-AF23 -> -17.056673
B24: 6811.HK | C24: =D173/(((D187+D199)+(C187+C199))/2) -> 13.938212 | D24: =E173/(((E187+E199)+(D187+D199))/2) -> 11.314714 | E24: =F173/(((F187+F199)+(E187+E199))/2) -> 13.012502 | F24: =G173/(((G187+G199)+(F187+F199))/2) -> 13.343983 | G24: =H173/(((H187+H199)+(G187+G199))/2) -> 15.170657 | H24: =360/C24 -> 25.828277 | I24: =360/D24 -> 31.816979 | J24: =360/E24 -> 27.665702 | K24: =360/F24 -> 26.978451 | L24: =360/G24 -> 23.730021 | M24: =D174/((D188+C188)/2) -> 10.000102 | N24: =E174/((E188+D188)/2) -> 7.8758994 | O24: =F174/((F188+E188)/2) -> 9.5603737 | P24: =G174/((G188+F188)/2) -> 10.286736 | Q24: =H174/((H188+G188)/2) -> 11.004444 | R24: =360/M24 -> 35.999631 | S24: =360/N24 -> 45.709065 | T24: =360/O24 -> 37.655432 | U24: =360/P24 -> 34.996523 | V24: =360/Q24 -> 32.714055 | W24: =D174/(((D190+D201)+(C190+C201))/2) -> 2.7171994 | X24: =E174/(((E190+E201)+(D190+D201))/2) -> 2.2634575 | Y24: =F174/(((F190+F201)+(E190+E201))/2) -> 2.5944416 | Z24: =G174/(((G190+G201)+(F190+F201))/2) -> 2.7189549 | AA24: =H174/(((H190+H201)+(G190+G201))/2) -> 3.0027591 | AB24: =360/W24 -> 132.48936 | AC24: =360/X24 -> 159.04871 | AD24: =360/Y24 -> 138.75818 | AE24: =360/Z24 -> 132.40381 | AF24: =360/AA24 -> 119.88974 | AG24: =H24+R24-AB24 -> -70.661449 | AH24: =I24+S24-AC24 -> -81.522668 | AI24: =J24+T24-AD24 -> -73.437051 | AJ24: =K24+U24-AE24 -> -70.428841 | AK24: =L24+V24-AF24 -> -63.445661
A26: Liquidity Analysis | C26: Current ratio | H26: Quick ratio | M26: Cash ratio
B27: Stock | C27: 2022 | D27: 2023 | E27: 2024 | F27: 2025 | G27: 2026 | H27: 2022 | I27: 2023 | J27: 2024 | K27: 2025 | L27: 2026 | M27: 2022 | N27: 2023 | O27: 2024 | P27: 2025 | Q27: 2026
B28: 0052.HK | C28: =D60/D64 -> 0.98358988 | D28: =E60/E64 -> 0.96968151 | E28: =F60/F64 -> 0.92783188 | F28: =G60/G64 -> 0.86528421 | G28: =H60/H64 -> 0.89272219 | H28: =(D73+D72+D70)/D64 -> 0.71019478 | I28: =(E73+E72+E70)/E64 -> 0.72583894 | J28: =(F73+F72+F70)/F64 -> 0.65068044 | K28: =(G73+G72+G70)/G64 -> 0.42670788 | L28: =(H73+H72+H70)/H64 -> 0.38656593 | M28: =(D73+D72)/D64 -> 0.68809646 | N28: =(E73+E72)/E64 -> 0.71401476 | O28: =(F73+F72)/F64 -> 0.62684381 | P28: =(G73+G72)/G64 -> 0.41560236 | Q28: =(H73+H72)/H64 -> 0.37636916
B29: 0341.HK | C29: =D93/D100 -> 1.2465296 | D29: =E93/E100 -> 0.76537955 | E29: =F93/F100 -> 0.89474989 | F29: =G93/G100 -> 0.8315996 | G29: =H93/H100 -> 0.80733456 | H29: =(D104+D92+D102)/D100 -> 0.94819329 | I29: =(E104+E92+E102)/E100 -> 0.62876772 | J29: =(F104+F92+F102)/F100 -> 0.70771079 | K29: =(G104+G92+G102)/G100 -> 0.61597647 | L29: =(H104+H92+H102)/H100 -> 0.61797757 | M29: =(D104+D92)/D100 -> 0.91864135 | N29: =(E104+E92)/E100 -> 0.60147507 | O29: =(F104+F92)/F100 -> 0.660842 | P29: =(G104+G92)/G100 -> 0.58389485 | Q29: =(H104+H92)/H100 -> 0.59020805
B30: 1314.HK | C30: =D124/D129 -> 1.0396185 | D30: =E124/E129 -> 1.3330155 | E30: =F124/F129 -> 1.278036 | F30: =G124/G129 -> 1.0481905 | G30: =H124/H129 -> 1.1576593 | H30: =(D135+D123+D121)/D129 -> 0.31588053 | I30: =(E135+E123+E121)/E129 -> 0.89139784 | J30: =(F135+F123+F121)/F129 -> 0.60233501 | K30: =(G135+G123+G121)/G129 -> 0.54809337 | L30: =(H135+H123+H121)/H129 -> 0.7260246 | M30: =(D135+D123)/D129 -> 0.30144093 | N30: =(E135+E123)/E129 -> 0.87702118 | O30: =(F135+F123)/F129 -> 0.59146414 | P30: =(G135+G123)/G129 -> 0.53092444 | Q30: =(H135+H123)/H129 -> 0.71502604
B31: 1978.HK | C31: =D155/D159 -> 1.4320817 | D31: =E155/E159 -> 1.4864319 | E31: =F155/F159 -> 1.1071638 | F31: =G155/G159 -> 0.70830618 | G31: =H155/H159 -> 0.81785378 | H31: =(D165+D154+D170)/D159 -> 1.1208137 | I31: =(E165+E154+E170)/E159 -> 1.18693 | J31: =(F165+F154+F170)/F159 -> 0.86039465 | K31: =(G165+G154+G170)/G159 -> 0.45365404 | L31: =(H165+H154+H170)/H159 -> 0.52741723 | M31: =(D165+D154)/D159 -> 1.1208137 | N31: =(E165+E154)/E159 -> 1.18693 | O31: =(F165+F154)/F159 -> 0.86039465 | P31: =(G165+G154)/G159 -> 0.45365404 | Q31: =(H165+H154)/H159 -> 0.52741723
B32: 6811.HK | C32: =D189/D194 -> 0.86312562 | D32: =E189/E194 -> 0.71213342 | E32: =F189/F194 -> 0.70740831 | F32: =G189/G194 -> 0.70327486 | G32: =H189/H194 -> 0.75116351 | H32: =(D200+D203+D187)/D194 -> 0.38336323 | I32: =(E200+E203+E187)/E194 -> 0.24540995 | J32: =(F200+F203+F187)/F194 -> 0.26787606 | K32: =(G200+G203+G187)/G194 -> 0.2695479 | L32: =(H200+H203+H187)/H194 -> 0.24491672 | M32: =(D200+D203)/D194 -> 0.35041648 | N32: =(E200+E203)/E194 -> 0.20970673 | O32: =(F200+F203)/F194 -> 0.22008911 | P32: =(G200+G203)/G194 -> 0.23226956 | Q32: =(H200+H203)/H194 -> 0.21169123
A34: Solvency Analysis | C34: Total Debt | H34: Debt-to-equity Ratio | M34: Interest Coverage Ratio
B35: Stock | C35: 2022 | D35: 2023 | E35: 2024 | F35: 2025 | G35: 2026 | H35: 2022 | I35: 2023 | J35: 2024 | K35: 2025 | L35: 2026 | M35: 2022 | N35: 2023 | O35: 2024 | P35: 2025 | Q35: 2026
B36: 0052.HK | C36: =D63+D62 -> 1186.23 | D36: =E63+E62 -> 1126.453 | E36: =F63+F62 -> 1042.181 | F36: =G63+G62 -> 943.549 | G36: =H63+H62 -> 950.978 | H36: =C36/D66 -> 1.6608376 | I36: =D36/E66 -> 1.6550176 | J36: =E36/F66 -> 1.5780937 | K36: =F36/G66 -> 1.4470834 | L36: =G36/H66 -> 1.4220763 | M36: =D49/D50 -> 2.47525 | N36: =E49/E50 -> 2.629882 | O36: =F49/F50 -> 2.9518372 | P36: =G49/G50 -> 2.1476379 | Q36: =H49/H50 -> 2.5816533
B37: 0341.HK | C37: =D97+D96 -> 3103.101 | D37: =E97+E96 -> 3249.034 | E37: =F97+F96 -> 2448.127 | F37: =G97+G96 -> 2134.31 | G37: =H97+H96 -> 1897.675 | H37: =C37/D95 -> 1.0979081 | I37: =D37/E95 -> 1.1636679 | J37: =E37/F95 -> 0.84113247 | K37: =F37/G95 -> 0.7776012 | L37: =G37/H95 -> 0.69551343 | M37: =D79/D81 -> 1.4898687 | N37: =E79/E81 -> 2.0692431 | O37: =F79/F81 -> 4.1698836 | P37: =G79/G81 -> 3.1204533 | Q37: =H79/H81 -> 2.6782925
B38: 1314.HK | C38: =D128+D127 -> 580.511 | D38: =E128+E127 -> 331.628 | E38: =F128+F127 -> 244.582 | F38: =G128+G127 -> 248.249 | G38: =H128+H127 -> 255.387 | H38: =C38/D131 -> 1.1447189 | I38: =D38/E131 -> 0.6208402 | J38: =E38/F131 -> 0.5039665 | K38: =F38/G131 -> 0.56328693 | L38: =G38/H131 -> 0.55736528 | M38: =D138/D111 -> 6.9200242 | N38: =E138/E111 -> 5.2679224 | O38: =F138/F111 -> 4.2954287 | P38: =G138/G111 -> 2.4029224 | Q38: =H138/H111 -> 1.9957627
B39: 1978.HK | C39: =D171+D158 -> 179.294 | D39: =E171+E158 -> 223.659 | E39: =F171+F158 -> 255.183 | F39: =G171+G158 -> 324.484 | G39: =H171+H158 -> 268.392 | H39: =C39/D162 -> 0.47158184 | I39: =D39/E162 -> 0.54617316 | J39: =E39/F162 -> 0.85802621 | K39: =F39/G162 -> 1.3934426 | L39: =G39/H162 -> 1.1442507 | M39: =D169/D143 -> 22.677806 | N39: =E169/E143 -> 11.202997 | O39: =F169/F143 -> 10.719151 | P39: =G169/G143 -> 3.9042979 | Q39: =H169/H143 -> 1.1754386
B40: 6811.HK | C40: =D191+D193 -> 1156.052 | D40: =E191+E193 -> 1108.422 | E40: =F191+F193 -> 1136.849 | F40: =G191+G193 -> 1103.808 | G40: =H191+H193 -> 1047.791 | H40: =C40/D197 -> 1.0555837 | I40: =D40/E197 -> 1.1604496 | J40: =E40/F197 -> 1.1546866 | K40: =F40/G197 -> 1.1797623 | L40: =G40/H197 -> 1.1671886 | M40: =D202/D177 -> 4.6810788 | N40: =E202/E177 -> 2.4760223 | O40: =F202/F177 -> 4.8628202 | P40: =G202/G177 -> 3.0885559 | Q40: =H202/H177 -> 4.4662868
A45: Financial Variables (in $ millions) | B45: Stock | C45: 2021 | D45: 2022 | E45: 2023 | F45: 2024 | G45: 2025 | H45: 2026
A46: Revenue | B46: 0052.HK | C46: 2646.469 | D46: 2881.942 | E46: 3024.152 | F46: 3136.947 | G46: 3100.07 | H46: 3098.831
A47: COGS | B47: 0052.HK | C47: 2318.873 | D47: 2659.381 | E47: 2767.394 | F47: 2866.353 | G47: 2862.864 | H47: 2830.39
A48: Gross Profit | B48: 0052.HK | C48: 327.596 | D48: 222.561 | E48: 256.758 | F48: 270.594 | G48: 237.206 | H48: 268.441
...

Sheet DCF
A1: DCF Model | B1: Year 1 | C1: Year 2 | D1: Year 3 | E1: Year 4 | F1: Year 5 | G1: Terminal Value
A2: in millions HKD | B2: 46477 | C2: 46843 | D2: 47208 | E2: 47573 | F2: 47938 | I2: 46112
A3: Revenue (Hong Kong segment) | B3: =I3*(1+B62) -> 3028.0822 | C3: =B3*(1+C62) -> 3099.8196 | D3: =C3*(1+D62) -> 3170.7053 | E3: =D3*(1+E62) -> 3243.1761 | F3: =E3*(1+F62) -> 3311.2827 | G3: =F3*(1+G62) -> 3380.8197 | I3: 2931.97
A4: Revenue (China segment) | B4: =I4*(1+B63) -> 186.95583 | C4: =B4*(1+C63) -> 197.89275 | D4: =C4*(1+D63) -> 204.55412 | E4: =D4*(1+E63) -> 209.75978 | F4: =E4*(1+F63) -> 213.53545 | G4: =F4*(1+G63) -> 217.37909 | I4: 166.861
A5: EBITDA | B5: =(B3+B4)*($I$5/($I$4+$I$3)) -> 624.42681 | C5: =(C3+C4)*($I$5/($I$4+$I$3)) -> 640.48386 | D5: =(D3+D4)*($I$5/($I$4+$I$3)) -> 655.5451 | E5: =(E3+E4)*($I$5/($I$4+$I$3)) -> 670.63147 | F5: =(F3+F4)*($I$5/($I$4+$I$3)) -> 684.59251 | G5: =(G3+G4)*($I$5/($I$4+$I$3)) -> 698.84454 | I5: ='Comparable Company Analysis'!H49+'Comparable Company Analysis'!H68 -> 601.857
A6: Depreciation and Amortisation | B6: =(B3+B4)*($I$6/($I$4+$I$3)) -> 537.00704 | C6: =(C3+C4)*($I$6/($I$4+$I$3)) -> 550.8161 | D6: =(D3+D4)*($I$6/($I$4+$I$3)) -> 563.76877 | E6: =(E3+E4)*($I$6/($I$4+$I$3)) -> 576.74304 | F6: =(F3+F4)*($I$6/($I$4+$I$3)) -> 588.74954 | G6: =(G3+G4)*($I$6/($I$4+$I$3)) -> 601.00628 | I6: ='Comparable Company Analysis'!H68 -> 517.597
A7: EBIT | B7: =B5-B6 -> 87.419775 | C7: =C5-C6 -> 89.667762 | D7: =D5-D6 -> 91.776336 | E7: =E5-E6 -> 93.888429 | F7: =F5-F6 -> 95.842975 | G7: =G5-G6 -> 97.838259
A8: Income tax | B8: =B7*B4/(B3+B4)*0.25+B7*B3/(B3+B4)*0.165 -> 14.85636 | C8: =C7*C4/(C3+C4)*0.25+C7*C3/(C3+C4)*0.165 -> 15.252556 | D8: =D7*D4/(D3+D4)*0.25+D7*D3/(D3+D4)*0.165 -> 15.615866 | E8: =E7*E4/(E3+E4)*0.25+E7*E3/(E3+E4)*0.165 -> 15.976393 | F8: =F7*F4/(F3+F4)*0.25+F7*F3/(F3+F4)*0.165 -> 16.30762 | G8: =G7*G4/(G3+G4)*0.25+G7*G3/(G3+G4)*0.165 -> 16.645725
A9: After-tax Income | B9: =B7-B8+B6 -> 609.57045 | C9: =C7-C8+C6 -> 625.2313 | D9: =D7-D8+D6 -> 639.92924 | E9: =E7-E8+E6 -> 654.65508 | F9: =F7-F8+F6 -> 668.2849 | G9: =G7-G8+G6 -> 682.19881
A10: Capital Expenditure | B10: =(B3+B4)*($I$10/($I$3+$I$4)) -> 158.42837 | C10: =(C3+C4)*($I$10/($I$3+$I$4)) -> 162.50233 | D10: =(D3+D4)*($I$10/($I$3+$I$4)) -> 166.32364 | E10: =(E3+E4)*($I$10/($I$3+$I$4)) -> 170.15133 | F10: =(F3+F4)*($I$10/($I$3+$I$4)) -> 173.6935 | G10: =(G3+G4)*($I$10/($I$3+$I$4)) -> 177.30949 | I10: ='Comparable Company Analysis'!H69 -> 152.702
A11: Free Cash Flow to debt and equity | B11: =B9-B10 -> 451.14208 | C11: =C9-C10 -> 462.72897 | D11: =D9-D10 -> 473.60559 | E11: =E9-E10 -> 484.50375 | F11: =F9-F10 -> 494.5914 | G11: =G9-G10 -> 504.88932
A13: Year | B13: 1 | C13: 2 | D13: 3 | E13: 4 | F13: 5 | G13: Terminal
A14: Discounted Free Cash Flow | B14: =B11/(1+$B$41)^B13 -> 425.65983 | C14: =C11/(1+$B$41)^C13 -> 411.93183 | D14: =D11/(1+$B$41)^D13 -> 397.80002 | E14: =E11/(1+$B$41)^E13 -> 383.96749 | F14: =F11/(1+$B$41)^F13 -> 369.82239 | G14: =(G11/(B41-G64))/(1+B41)^F13 -> 9668.5263
A15: Value of the Firm | G15: =SUM(B14:G14) -> 11657.708
A18: Appendix 1: Weighted-average Cost of Capital (WACC) Calculation
A19: Cost of debt
A20: Interest expense on lease liabilities (31 Mar 2026) | B20: 32.171
A21: Interest expense on bank borrowings (31 Mar 2026) | B21: 0.467
A22: Total Debt (31 Mar 2026) | B22: ='Comparable Company Analysis'!G36 -> 950.978
A23: Pre-tax Cost of Debt | B23: =(B20+B21)/B22 -> 0.034320457
A24: Effective Tax Rate | B24: =F4/(F3+F4)*0.25+F3/(F3+F4)*0.165 -> 0.17014935
A25: After-tax Cost of Debt | B25: =B23*(1-B24) -> 0.028480854
A27: Cost of Equity | C27: HK ERP | D27: China ERP
A28: Risk Free Rate | B28: ='Risk-free Rate'!E9 -> 0.023146583
A29: Equity Risk Premium (ERP) | B29: =C29*(G3/(G3+G4))+D29*(G4/(G3+G4)) -> 0.048460413 | C29: 0.0484 | D29: 0.0494
A30: Effective Tax Rate in the year ended 31 Mar 2026 | B30: ='Comparable Company Analysis'!H52/'Comparable Company Analysis'!H51 -> 0.1949169
A31: Debt-to-equity Ratio | B31: ='Comparable Company Analysis'!L36 -> 1.4220763
A32: Equity Beta | B32: 0.454
A33: Asset Beta | B33: =B32/(1+(1-B30)*B31) -> 0.2116659
A34: Damodoran's Asset Beta | B34: 0.77
A35: Relevered Equity Beta | B35: =B34*(1+(1-B24)*B31) -> 1.6786855
A36: Cost of Equity | B36: =B28+B35*B29 -> 0.10449637
A38: WACC
A39: WACC Debt proportion | B39: =B31/(B31+1) -> 0.5871311
A40: WACC Equity proportion | B40: =1-B39 -> 0.4128689
A41: WACC | B41: =B36*B40+B39*B25 -> 0.059865298
A43: Appendix 2: Computation of the Terminal Growth Rate
A44: Number of shops | B44: 46112
A45: Number of shops in Hong Kong | B45: 156
A46: Number of shops in China | B46: 28
...

Sheet Assumptions
A1: Assumptions in the DCF Model
B3: Parameter | C3: Value | D3: Explanation
B4: Risk-Free Rate | C4: ='Risk-free Rate'!E9 -> 0.023146583 | D4: The average of Hong Kong Government 10-year Bond (Monthly, September 2016 – August 2026)
B5: Beta | C5: =DCF!B35 -> 1.6786855 | D5: Derived from the unlever beta from Damodaran's unlevered beta in restaurant or dining industry. The unlevered beta is relevered to equity beta via asset-beta formula, that the Debt-to-equity Ratio in in the year end 31 Mar 2026 is used.
B6: Equity Risk Premium (ERP) | C6: =DCF!B29 -> 0.048460413 | D6: Derived from the Equity Risk Premium of Hong Kong and China from Damodaran's Equity Risk Premium. The weighting of the Equity Risk Premium of two locations is determined by the weighting of the revenue from Hong Kong and China operating segments estimated in the terminal year.
B7: Cost of Equity | C7: =DCF!B36 -> 0.10449637 | D7: Derived from the Capital Asset Pricing Model.
B8: Cost of Debt (after-tax) | C8: =DCF!B25 -> 0.028480854 | D8: Derived from the effective interest rate calculated from the interest expense of bank borrowings and lease liabilities in the year end 31 Mar 2026. For Tax Rate assumptions, please refer to the Tax Rate explanation.
B9: Debt-to-equity Ratio | C9: =DCF!B31 -> 1.4220763 | D9: The debt portion includes bank borrowings and lease liabilities in the year end 31 Mar 2026. The equity portion is the equity after considering the non-controlling interest in the year end 31 Mar 2026.
B10: Weighted-Average Cost of Capital | C10: =DCF!B41 -> 0.059865298 | D10: Derived from the WACC Formula from the Cost of Equity and Cost of Debt, the weighting of Debt and Equity are according to the proportion of Debt and Equity defined in the calculation of Debt-to-equity Ratio in the year ended 31 Mar 2026.
B11: Terminal Growth Rate | C11: =DCF!G64 -> 0.02081876 | D11: Determined from the estimation of inflation rate from International Monetary Fund and the estimation of the number of stores to be opened in Hong Kong and China from FairWood Financial Report in 2026. The proportion of the Terminal Growth Rate is determined by the weighting of the revenue from Hong Kong and China operating segments estimated in the terminal year. Please refer to the detailed computation of the Terminal Growth Rate in Appendix 2.
B12: Tax Rate | C12: =DCF!B24 -> 0.17014935 | D12: Determined by the weighting of the revenue from Hong Kong and China operating segments estimated in the terminal year, where the tax rate in Hong Kong and China are 16.5% and 25% respectively. For the tax rate in the first 5 years forecasted in the DCF model, the tax rate is determined by the weighting of the revenue from Hong Kong and China operating segments estimated in each of the years.
B13: Revenue | D13: Determined by the Growth Rate calculated in Appendix 2.
B14: EBITDA | D14: Determined by the revenue proportion in each of the years forecasted.
B15: Depreciation and Amortisation
B16: Capital Expenditure
B18: Damodaran's Equity Risk Premium and Unlevered Beta
B19: https://pages.stern.nyu.edu/~adamodar/New_Home_Page/datacurrent.html

Sheet Risk-free Rate
A1: Risk-Free Rate Hong Kong Government 10-year Bond Yield (Monthly, September 2016 – August 2026)
A2: Date | B2: Yield
A3: 46235 | B3: 3.618
A4: 46204 | B4: 3.508
A5: 46174 | B5: 3.293
A6: 46143 | B6: 3.275
A7: 46113 | B7: 3.003 | D7: https://www.investing.com/rates-bonds/hong-kong-10-year-bond-yield-historical-data
A8: 46082 | B8: 2.897
A9: 46054 | B9: 2.818 | D9: Average | E9: =AVERAGE(B3:B122)/100 -> 0.023146583
A10: 46023 | B10: 3.192
A11: 45992 | B11: 3.099
A12: 45962 | B12: 2.935
A13: 45931 | B13: 2.98
A14: 45901 | B14: 3.053
A15: 45870 | B15: 3.071
A16: 45839 | B16: 3.051
A17: 45809 | B17: 2.973
A18: 45778 | B18: 3.008
A19: 45748 | B19: 3.157
A20: 45717 | B20: 3.386
A21: 45689 | B21: 3.48
... A122: 42614 | B122: 0.961
